Workbook

Sheet Master_Extraction
A1: Paper_ID | B1: File_Name | C1: PDF_Path_or_Link | D1: Extraction_Status | E1: Extraction_Date | F1: Reviewer_Check_Status | G1: Human_Reviewer | H1: Confidence_Overall_1_5 | I1: Notes_For_Human_Check | J1: DOI | K1: Title | L1: Authors | M1: Year | N1: Publication_Type | O1: Venue_Journal_Conference | P1: Publisher | Q1: Discipline_Field | R1: Keywords_Author_Provided | S1: Abstract_Short | T1: Inclusion_Decision | U1: Relevance_to_Review_1_5 | V1: LCNC_Focus_Level | W1: Study_Object | X1: Primary_LCNC_Topic | Y1: Secondary_Topics | Z1: Review_Question_Link | AA1: Why_This_Paper_Matters | AB1: Definition_of_Low_Code | AC1: Definition_of_No_Code | AD1: Related_Terms_Used | AE1: Theoretical_Framework | AF1: Key_Constructs | AG1: Boundary_or_Scope_Conditions | AH1: Paper_Category | AI1: Research_Type | AJ1: Study_Design | AK1: Research_Method | AL1: Data_Type | AM1: Unit_of_Analysis | AN1: Industry_Domain | AO1: Application_Domain | AP1: Target_User_Group | AQ1: Platform_or_Tool_Studied | AR1: Technology_Stack_or_Ecosystem | AS1: Research_Questions_or_Hypotheses | AT1: Data_Source | AU1: Sample_Size | AV1: Sampling_Strategy | AW1: Participants_Profile | AX1: Time_Period | AY1: Location_Context | AZ1: Instruments_Used | BA1: Variables_or_Measures | BB1: Analysis_Techniques | BC1: Validity_Reliability_Checks | BD1: Main_Findings_Detailed | BE1: Claimed_Benefits | BF1: Claimed_Challenges | BG1: Security_Privacy_Findings | BH1: Governance_Findings | BI1: Scalability_Maintainability_Findings | BJ1: Productivity_Findings | BK1: Quality_Findings | BL1: Skills_Role_Findings | BM1: Education_Training_Findings | BN1: AI_Automation_Findings | BO1: Economic_or_Business_Findings | BP1: Contradictions_or_Nuances | BQ1: Authors_Interpretation | BR1: Key_Quote_1 | BS1: Key_Quote_1_Page | BT1: Key_Quote_2 | BU1: Key_Quote_2_Page | BV1: Most_Important_Table_Figure | BW1: Important_Statistics_or_Numbers | BX1: Evidence_Strength | BY1: Evidence_Notes | BZ1: Authors_Limitations | CA1: Your_Critical_Limitations | CB1: Research_Gaps_Identified | CC1: Future_Work_Suggested | CD1: Practical_Implications | CE1: Theoretical_Implications | CF1: Policy_Governance_Implications | CG1: Theme_Code_1 | CH1: Theme_Code_2 | CI1: Theme_Code_3 | CJ1: Theme_Code_4 | CK1: Method_Code | CL1: Domain_Code | CM1: Quality_Score_Total | CN1: Quality_Rating | CO1: Use_In_Final_Review | CP1: Best_Section_For_Citation | CQ1: Suggested_Claim_This_Paper_Supports | CR1: Contrasts_With_Papers | CS1: Cluster_Group | CT1: One_Sentence_Takeaway | CU1: Agent_Uncertainty_Flags | CV1: Citation_BibTeX | CW1: APA_Reference | CX1: Source_URL
A2: P001 | B2: 1.AI-FOR-SCIENCE LOW-CODE PLATFORM WITH.pdf | C2: research paper\1.AI-FOR-SCIENCE LOW-CODE PLATFORM WITH.pdf | D2: Completed | E2: 2026-06-12 | F2: Checked - OK | G2: Reported | H2: 4 | I2: Verify automated title/authors/method/sample/theme coding and exact quote page numbers before publication use. | J2: Not reported | K2: AI-for-Science Low-code Platform with Bayesian Adversarial Multi-Agent Framework | L2: Zihang Zeng1,2#, Jiaquan Zhang1,2#, Pengze Li1, Yuan Qi1,3, Xi Chen1,3† | M2: 2025 | N2: Preprint | O2: Published as a conference paper at ICLR 2026; arXiv:2603.03233v1 [cs.AI] 3 Mar 2026; Published as a conference paper at ICLR 2026 | P2: Not reported | Q2: Unclear: discipline not explicitly labeled; paper text concerns LCNC/software systems | R2: Not reported | S2: Multi-agent systems leveraging Large Language Models (LLMs) show immense potential for solving complex scientific problems. However, their reliability is undermined by the probabilistic nature of LLMs, which can produce hallucinations in both generated code and its corresponding test cases. In a multi-agent architecture, these errors can propagate and compound, leading to flawed final outputs. To overcome these core limitations, we introduce a novel Bayesian Adversarial Multi-agent Framework for AI for Science (AI4S). Delivered as a Low-code Platform (LCP), our framework enhances the coding capability for scientific tasks across a wide range of base models, from 1.7B open-source LLMs to up-to-date commercial ones. Our framework employs three agents in a recursive loop that adversarially co-optimizes the generated solutions, the test cases used for evaluation, and the prompts driving generation. This process is governed by a non-LLM-based Bayesian updating rule, which systematically reduces evaluation uncertainty and mitigates the system’s dependence on any single LLM’s reliability. Furthermore, the LCP empowers domain experts by translating high-level natural language prompts into executable, domain-specific requirements, eliminating the need for intricate prompt engineering. Extensive experiments confirm that our framework generates robust solutions while effectively minimizing error propagation. On a complex, cross-disciplinary Earth Science benchmark, our platform demonstrates superior reliability and outperforms state-of-the-art models, where a 32B opensource model c... | T2: Include | U2: 5 | V2: Core focus | W2: AI-for-Science Low-code Platform with Bayesian Adversarial Multi-Agent Framework | X2: AI and automation | Y2: Quality assurance and testing; Platform comparison; Education and training | Z2: Supports review questions on LCNC adoption, AI automation, methods, benefits, risks, and gaps depending on assigned theme codes. | AA2: Extensive experiments confirm that our framework generates robust solutions while effectively minimizing error propagation. | On a complex, cross-disciplinary Earth Science benchmark, our platform demonstrates superior reliability and outperforms state-of-the-art models, where a 32B opensource model can beat the performance of a 235B model in the ScienceCode benchmark with our framework. | Standard unit tests may miss critical scientific constraints, theoretical foundations, or domain-specifi... | AB2: Published as a conference paper at ICLR 2026 AI-FOR-SCIENCELOW-CODEPLATFORM WITH BAYESIANADVERSARIALMULTI-AGENTFRAMEWORK Zihang Zeng1,2#, Jiaquan Zhang1,2#, Pengze Li1, Yuan Qi1,3, Xi Chen1,3† 1Artificial Intelligence Innovation and Incubation Institute, Fudan University 2Shanghai Innovation Institute 3Shanghai Academy of AI for Science x_chen@fudan.edu.cn ABSTRACT Multi-agent systems leveraging Large Language Models (LLMs) show immense potential for solving complex scientific problems. | AC2: Not reported | AD2: low-code | AE2: Published as a conference paper at ICLR 2026 AI-FOR-SCIENCELOW-CODEPLATFORM WITH BAYESIANADVERSARIALMULTI-AGENTFRAMEWORK Zihang Zeng1,2#, Jiaquan Zhang1,2#, Pengze Li1, Yuan Qi1,3, Xi Chen1,3† 1Artificial Intelligence Innovation and Incubation Institute, Fudan University 2Shanghai Innovation Institute 3Shanghai Academy of AI for Science x_chen@fudan.edu.cn ABSTRACT Multi-agent systems leveraging Large Language Models (LLMs) show immense potential for solving complex scientific problems. | AF2: low-code | AG2: Multi-agent systems leveraging Large Language Models (LLMs) show immense potential for solving complex scientific problems. However, their reliability is undermined by the probabilistic nature of LLMs, which can produce hallucinations in both generated code and its corresponding test cases. In a multi-agent architecture, these errors can propagate and compound, leading to flawed final outputs. To overcome these core limitations, we introduce a novel Bayesian Adversarial Multi-agent Framework for AI for Science (AI4S). Delivered as a Low-code Platform (LCP), our framework enhances the coding capability for scientific tasks across a wide range of base models, from 1.7B open-source LLMs to up-to-date commercial ones. Our framework employs three agents in a recursive loop that adversarially co-optimizes the generated solutions, the test cases used for evaluation, and the prompts driving generation. This process is governed by a non-LLM-based Bayesian updating rule, which systematically reduces evaluation uncertainty and mitigates the system’s dependence on any single LLM’s reliability. Furthermore, the LCP empowers domain experts by translating high-level natural language prompts into executable, domain-specific requirements, eliminating the need for intricate prompt engineering. Extensive experiments confirm that our framework generates robust solutions while effectively minimizing error propagation. On a complex, cross-disciplinary Earth Science benchmark, our platform demonstrates superior reliability and outperforms state-of-the-art models, where a 32B opensource model c... | AH2: Tool/Platform Proposal | AI2: Technical/Engineering | AJ2: Benchmarking | AK2: Benchmarking | AL2: Primary Data | AM2: Prototype/tool/platform or benchmark tasks | AN2: scientific; AI for Science | AO2: scientific; AI for Science | AP2: Furthermore, the LCP empowers domain experts by translating high-level natural language prompts into executable, domain-specific requirements, eliminating the need for intricate prompt engineering. | AQ2: Not reported | AR2: low-code | AS2: Not reported | AT2: On a complex, cross-disciplinary Earth Science benchmark, our platform demonstrates superior reliability and outperforms state-of-the-art models, where a 32B opensource model can beat the performance of a 235B model in the ScienceCode benchmark with our framework. | AU2: Not reported | AV2: Subsequently, the TM agent generates an initial set of test cases ( Test Case0) corresponding to these sub-tasks and other criteria derived from prior knowledge. | AW2: Furthermore, the LCP empowers domain experts by translating high-level natural language prompts into executable, domain-specific requirements, eliminating the need for intricate prompt engineering. | AX2: Not reported | AY2: Not reported | AZ2: On a complex, cross-disciplinary Earth Science benchmark, our platform demonstrates superior reliability and outperforms state-of-the-art models, where a 32B opensource model can beat the performance of a 235B model in the ScienceCode benchmark with our framework. | BA2: On a complex, cross-disciplinary Earth Science benchmark, our platform demonstrates superior reliability and outperforms state-of-the-art models, where a 32B opensource model can beat the performance of a 235B model in the ScienceCode benchmark with our framework. | The gains are particularly striking for open-source models, with relative improvements of up to87.1%(for Qwen3-8b). | As shown in Table 2, our LCP framework achieves new state-ofthe-art (SOTA) performance, particularly in the Valid Execution Rate (VER), where it scores90.2% (without knowledge) and87.3%(with knowledge), far surpassing all other methods. | Table 1: Model Performance Comparison on SciCode with various backbone models Without Knowledge With Knowledge Without Knowledge With Knowledge Model Method Sub (%) Main (%) Sub (%) Main (%) Model Method Sub (%) Main (%) Sub (%) Main (%) Qwen3-8b Baseline 13.2 0 19.8 1.5 GPT-4o Baseline 24.1 1.5 33.7 7.7Ours24.7(87.1%) 4.6 27.4(38.4%) 4.6Ours37.... | BB2: Delivered as a Low-code Platform (LCP), our framework enhances the coding capability for scientific tasks across a wide range of base models, from 1.7B open-source LLMs to up-to-date commercial ones. | BC2: However, their reliability is undermined by the probabilistic nature of LLMs, which can produce hallucinations in both generated code and its corresponding test cases. | BD2: Extensive experiments confirm that our framework generates robust solutions while effectively minimizing error propagation. | On a complex, cross-disciplinary Earth Science benchmark, our platform demonstrates superior reliability and outperforms state-of-the-art models, where a 32B opensource model can beat the performance of a 235B model in the ScienceCode benchmark with our framework. | Standard unit tests may miss critical scientific constraints, theoretical foundations, or domain-specific limitations. | BE2: This process is governed by a non-LLM-based Bayesian updating rule, which systematically reduces evaluation uncertainty and mitigates the system’s dependence on any single LLM’s reliability. | Furthermore, the LCP empowers domain experts by translating high-level natural language prompts into executable, domain-specific requirements, eliminating the need for intricate prompt engineering. | BF2: Published as a conference paper at ICLR 2026 AI-FOR-SCIENCELOW-CODEPLATFORM WITH BAYESIANADVERSARIALMULTI-AGENTFRAMEWORK Zihang Zeng1,2#, Jiaquan Zhang1,2#, Pengze Li1, Yuan Qi1,3, Xi Chen1,3† 1Artificial Intelligence Innovation and Incubation Institute, Fudan University 2Shanghai Innovation Institute 3Shanghai Academy of AI for Science x_chen@fudan.edu.cn ABSTRACT Multi-agent systems leveraging Large Language Models (LLMs) show immense potent... | However, their reliability is undermined by the probabilistic nature of LLMs, which can produce hallucinations in both generated code and its corresponding test cases. | BG2: Not reported | BH2: This plan is iteratively refined based on users’ feedback F and refinements until user’s approval and denoted as Plans, as indicated by Loop 1 of Figure 2. | BI2: On a complex, cross-disciplinary Earth Science benchmark, our platform demonstrates superior reliability and outperforms state-of-the-art models, where a 32B opensource model can beat the performance of a 235B model in the ScienceCode benchmark with our framework. | This fundamental insight motivates our core design philosophy: an adversarial co-evolution framework where test case generation and code improvement mutually refine each other through competitive optimization, replacing traditional static verification approaches. | BJ2: Not reported | BK2: 2.3 A PRIORI ESTIMATION WITHBAYESIANOPTIMIZATION We noticed that executing all the generated codes for testing can be computationally expensive. | BL2: It maintains accessibility for non-technical domain experts while fully leveraging their domain expertise without requiring any computer science or professional prompt engineering skills. | BM2: Furthermore, evaluating the generated machine learning or deep learning models can be highly resource-intensive, and performance variability due to training dynamics and data poses an additional challenge to the update mechanism. | BN2: Published as a conference paper at ICLR 2026 AI-FOR-SCIENCELOW-CODEPLATFORM WITH BAYESIANADVERSARIALMULTI-AGENTFRAMEWORK Zihang Zeng1,2#, Jiaquan Zhang1,2#, Pengze Li1, Yuan Qi1,3, Xi Chen1,3† 1Artificial Intelligence Innovation and Incubation Institute, Fudan University 2Shanghai Innovation Institute 3Shanghai Academy of AI for Science x_chen@fudan.edu.cn ABSTRACT Multi-agent systems leveraging Large Language Models (LLMs) show immense potential for solving complex scientific problems. | BO2: This suggests an optimal balance between performance and computational cost. | BP2: However, their reliability is undermined by the probabilistic nature of LLMs, which can produce hallucinations in both generated code and its corresponding test cases. | BQ2: Extensive experiments confirm that our framework generates robust solutions while effectively minimizing error propagation. | On a complex, cross-disciplinary Earth Science benchmark, our platform demonstrates superior reliability and outperforms state-of-the-art models, where a 32B opensource model can beat the performance of a 235B model in the ScienceCode benchmark with our framework. | Standard unit tests may miss critical scientific constraints, theoretical foundations, or domain-specific limitations. | BR2: Published as a conference paper at ICLR 2026 AI-FOR-SCIENCELOW-CODEPLATFORM WITH BAYESIANADVERSARIALMULTI-AGENTFRAMEWORK Zihang Zeng1,2#, Jiaquan Zhang1,2#, Pengze Li1, Yuan Qi1,3, Xi Chen1,3† 1Artificial Intelligence Innovation and Incubation Institute, Fudan University 2Shanghai Innovation Institute 3Shanghai Academy of AI for Science x_chen@fudan.edu.cn ABSTRACT Multi-agent systems leveraging Large Language Models (LLMs) show immense potential for solving complex scientific problems. | BS2: 1 | BT2: 2.3 A PRIORI ESTIMATION WITHBAYESIANOPTIMIZATION We noticed that executing all the generated codes for testing can be computationally expensive. | BU2: 5 | BV2: Not reported | BW2: On a complex, cross-disciplinary Earth Science benchmark, our platform demonstrates superior reliability and outperforms state-of-the-art models, where a 32B opensource model can beat the performance of a 235B model in the ScienceCode benchmark with our framework. | The gains are particularly striking for open-source models, with relative improvements of up to87.1%(for Qwen3-8b). | As shown in Table 2, our LCP framework achieves new state-ofthe-art (SOTA) performance, particularly in the Valid Execution Rate (VER), where it scores90.2% (without knowledge) and87.3%(with knowledge), far surpassing all other methods. | Table 1: Model Performance Comparison on SciCode with various backbone models Without Knowledge With Knowledge Without Knowledge With Knowledge Model Method Sub (%) Main (%) Sub (%) Main (%) Model Method Sub (%) Main (%) Sub (%) Main (%) Qwen3-8b Baseline 13.2 0 19.8 1.5 GPT-4o Baseline 24.1 1.5 33.7 7.7Ours24.7(87.1%) 4.6 27.4(38.4%) 4.6Ours37.... | BX2: Strong | BY2: PDF text extracted from 38 pages; sample evidence page: Not reported. | BZ2: , we introduce a novel Bayesian Adversarial Multi-agent Framework for AI for Science (AI4S). Delivered as a Low-code Platform (LCP), our framework enhances the coding capability for scientific tasks across a wide range of base models, from 1.7B open-source LLMs to up-to-date commercial ones. Our framework employs three agents in a recursive loop that adversarially co-optimizes the generated solutions, the test cases used for evaluation, and the prompts driving generation. This process is governed by a non-LLM-based Bayesian updating rule, which systematically reduces evaluation uncertainty and mitigates the system’s dependence on any single LLM’s reliability. Furthermore, the LCP empowers domain experts by translating high-level natural language prompts into executable, domain-specific requirements, eliminating the need for intricate prompt engineering. Extensive experiments confirm that our framework generates robust solutions while effectively minimizing error propagation. On a complex, cross-disciplinary Earth Science benchmark, our platform demonstrates superior reliability and outperforms state-of-the-art models, where a 32B opensource model can beat the performance of a 235B model in the ScienceCode benchmark with our framework. 1 INTRODUCTION Large Language Models (LLMs) are transforming AI for Science (AI4S) research paradigm by automating complex scientific code gen... | CA2: Sample/data adequacy could not be verified from parsed text | CB2: will focus on extending the Bayesian updates to handle multi-modal inputs, such as equations and diagrams, and optimizing the iteration protocols for large-scale scientific simulations. | CC2: will focus on extending the Bayesian updates to handle multi-modal inputs, such as equations and diagrams, and optimizing the iteration protocols for large-scale scientific simulations. | CD2: While this increased token budget can be a practical constraint for long pipelines, in reliability-critical scientific applications, we prioritize executable correctness and robustness over marginal token savings. | CE2: Not reported | CF2: This plan is iteratively refined based on users’ feedback F and refinements until user’s approval and denoted as Plans, as indicated by Loop 1 of Figure 2. | CG2: AI_AUTOMATION | CH2: QUALITY_TESTING | CI2: PLATFORM_COMPARISON | CJ2: EDUCATION | CK2: Benchmarking | CL2: Not reported | CM2: =IFERROR(VLOOKUP($A2,Quality_Appraisal!$A:$P,15,FALSE),"") -> 23 | CN2: =IFERROR(VLOOKUP($A2,Quality_Appraisal!$A:$P,16,FALSE),"") -> Strong | CO2: Yes - central | CP2: Findings/Future | CQ2: Extensive experiments confirm that our framework generates robust solutions while effectively minimizing error propagation. | On a complex, cross-disciplinary Earth Science benchmark, our platform demonstrates superior reliability and outperforms state-of-the-art models, where a 32B opensource model can beat the performance of a 235B model in the ScienceCode benchmark with our framework. | Standard unit tests may miss critical scientific constraints, theoretical foundations, or domain-specifi... | CR2: Not reported | CS2: AI and automation | CT2: Extensive experiments confirm that our framework generates robust solutions while effectively minimizing error propagation. | On a complex, cross-disciplinary Earth Science benchmark, our platform demonstrates superior reliability and outperforms state-of-the-art models, where a 32B opensource model can beat the performance of a 235B model in the ScienceCode benchmark with our framework. | Standard unit tests may miss critical scientific constraints, theoretical foundations, or domain-specifi... | CU2: sample/data size missing | CV2: Not reported | CW2: Zihang Zeng1,2#, Jiaquan Zhang1,2#, Pengze Li1, Yuan Qi1,3, Xi Chen1,3† (2025). AI-for-Science Low-code Platform with Bayesian Adversarial Multi-Agent Framework. Published as a conference paper at ICLR 2026; arXiv:2603.03233v1 [cs.AI] 3 Mar 2026; Published as a conference paper at ICLR 2026. | CX2: Not reported
A3: P002 | B3: 2.LOW-CODE AND NO-CODE WITH BESSER TO CREATE AND.pdf | C3: research paper\2.LOW-CODE AND NO-CODE WITH BESSER TO CREATE AND.pdf | D3: Completed | E3: 2026-06-12 | F3: Checked - OK | G3: Reported | H3: 4 | I3: Verify automated title/authors/method/sample/theme coding and exact quote page numbers before publication use. | J3: Not reported | K3: Low-code and no-code with BESSER to create and deploy smart web applications | L3: arXiv:2605.07376v1 [cs.SE] 8 May 2026 | M3: 2025 | N3: Preprint | O3: The peer-reviewed paper will be published in the proceedings of ICWE 2026.; arXiv:2605.07376v1 [cs.SE] 8 May 2026 | P3: Not reported | Q3: Unclear: discipline not explicitly labeled; paper text concerns LCNC/software systems | R3: Low-code·No-code·Web application·Agents 1 | S3: The increasing demand for web applications containing AI-agents, seen as smart web applications, has prompted the need for new techniques to facilitate their creation. Low-code has risen as an approach that reduces the amount of handwritten code by focusing on the abstraction of components in the form of models combined with automated generators to produce applications. Existing low-code platforms are commercial, leading to drawbacks such as the risk of vendor lock-in, limited extensibility, and more. We present the open-source BESSER low-code framework, which allows users to design, generate and deploy their application via a freely accessible web-based editor, while guaranteeing transparency and extensibility. KeywordsLow-code·No-code·Web application·Agents | T3: Include | U3: 5 | V3: Core focus | W3: Low-code and no-code with BESSER to create and deploy smart web applications | X3: Model-driven / visual programming roots | Y3: AI and automation; Maintainability; Platform comparison | Z3: Supports review questions on LCNC adoption, AI automation, methods, benefits, risks, and gaps depending on assigned theme codes. | AA3: Languages such as IFML [2], OOWS [3], or UWE [4] are often seen as foundational for the development of traditional UIs. | 2 Demonstration Figure 1 presents the part of BESSER’s pipeline for developing smart web applications used in the demonstration. | The demonstration contains the example of a web application of a library, with a conversational agent responding to frequently asked questions. | AB3: Existing low-code platforms are commercial, leading to drawbacks such as the risk of vendor lock-in, limited extensibility, and more. | AC3: From theGUIperspective, the editor provides a no-code interface that allows users to drag and drop UI components onto a blank page (Figure 2), which are immediately rendered. | AD3: low-code; no-code; model-driven engineering | AE3: We present the open-source BESSER low-code framework, which allows users to design, generate and deploy their application via a freely accessible web-based editor, while guaranteeing transparency and extensibility. | AF3: Low-code·No-code·Web application·Agents 1 | AG3: The increasing demand for web applications containing AI-agents, seen as smart web applications, has prompted the need for new techniques to facilitate their creation. Low-code has risen as an approach that reduces the amount of handwritten code by focusing on the abstraction of components in the form of models combined with automated generators to produce applications. Existing low-code platforms are commercial, leading to drawbacks such as the risk of vendor lock-in, limited extensibility, and more. We present the open-source BESSER low-code framework, which allows users to design, generate and deploy their application via a freely accessible web-based editor, while guaranteeing transparency and extensibility. KeywordsLow-code·No-code·Web application·Agents | AH3: Empirical Study | AI3: Qualitative | AJ3: Document Analysis | AK3: Document Analysis | AL3: Secondary Data | AM3: Not reported | AN3: Not reported | AO3: Not reported | AP3: We present the open-source BESSER low-code framework, which allows users to design, generate and deploy their application via a freely accessible web-based editor, while guaranteeing transparency and extensibility. | AQ3: BESSER | AR3: BESSER | AS3: Not reported | AT3: The only additional requirement to complete the demo is a free account on GitHub 2 and Render3, the former being used for hosting the models and generated code, and the latter for running frontend and backend servers. | AU3: Not reported | AV3: Thestructuralperspective specifies the static aspects of the web application through class diagrams, including classes, attributes, methods, relationships, and other elements, reusing core UML [ 6] concepts for this perspective while extending and simplifying selected aspects of the specification for smart web applications. | AW3: We present the open-source BESSER low-code framework, which allows users to design, generate and deploy their application via a freely accessible web-based editor, while guaranteeing transparency and extensibility. | AX3: Not reported | AY3: Not reported | AZ3: Yet, these do not cover the definition of smart components, and provide limited or fragmented tool support for the complete creation and deployment pipeline. | BA3: A video demonstration of the presented scenario is available4 3 Modeling, generating and deploying smart web applications with BESSER BESSER provides the B-UML (BESSER-UML) language, which enables the modeling of smart web applications via three complementary but still interrelated perspectives:structural,agent, andGUIperspectives. | BB3: Not reported | BC3: Not reported | BD3: Languages such as IFML [2], OOWS [3], or UWE [4] are often seen as foundational for the development of traditional UIs. | 2 Demonstration Figure 1 presents the part of BESSER’s pipeline for developing smart web applications used in the demonstration. | The demonstration contains the example of a web application of a library, with a conversational agent responding to frequently asked questions. | BE3: Low-code has risen as an approach that reduces the amount of handwritten code by focusing on the abstraction of components in the form of models combined with automated generators to produce applications. | KeywordsLow-code·No-code·Web application·Agents 1 Introduction The increasing demand for better software in recent years has created a need for advanced strategies to improve developer productivity. | BF3: Existing low-code platforms are commercial, leading to drawbacks such as the risk of vendor lock-in, limited extensibility, and more. | Low-code development, the latest reincarnation of model-driven engineering approaches, addresses this demand but introduces challenges related to the growing complexity of modern software requirements, such as AI-powered agents. | BG3: Not reported | BH3: These actions may include textual responses (e.g., for chat interactions), calls to Python methods (e.g., to invoke external APIs), or operations driven by Large Language Model (LLM) outputs, combining the controlled output from state machines with the openness of LLMs. | BI3: Existing low-code platforms are commercial, leading to drawbacks such as the risk of vendor lock-in, limited extensibility, and more. | BJ3: KeywordsLow-code·No-code·Web application·Agents 1 Introduction The increasing demand for better software in recent years has created a need for advanced strategies to improve developer productivity. | BK3: Not reported | BL3: Not reported | BM3: Not reported | BN3: The reference will be provided once available. arXiv:2605.07376v1 [cs.SE] 8 May 2026 | BO3: Not reported | BP3: Low-code development, the latest reincarnation of model-driven engineering approaches, addresses this demand but introduces challenges related to the growing complexity of modern software requirements, such as AI-powered agents. | BQ3: Languages such as IFML [2], OOWS [3], or UWE [4] are often seen as foundational for the development of traditional UIs. | 2 Demonstration Figure 1 presents the part of BESSER’s pipeline for developing smart web applications used in the demonstration. | The demonstration contains the example of a web application of a library, with a conversational agent responding to frequently asked questions. | BR3: Low-code development, the latest reincarnation of model-driven engineering approaches, addresses this demand but introduces challenges related to the growing complexity of modern software requirements, such as AI-powered agents. | BS3: 2 | BT3: LOW-CODE AND NO-CODE WITHBESSERTO CREATE AND DEPLOY SMART WEB APPLICATIONS Iván Alfonso Luxembourg Institute of Science and Technology, Luxembourg ivan.alfonso@list.lu Armen Sulejmani Luxembourg Institute of Science and Technology, Luxembourg armen.sulejmani@list.lu Aaron Conrardy Luxembourg Institute of Science and Technology, Luxembourg University of Luxembourg, Luxembourg aaron.conrardy@list.lu Jordi Cabot Luxembourg Institute of Science and Technology, Luxembourg University of Luxembourg, Luxembourg jordi.cabot@list.lu ABSTRACT The increasing demand for web applications containing AI-agents, seen as smart web applications, has prompted the need for new techniques to facilitate their creation. | BU3: 2 | BV3: Not reported | BW3: A video demonstration of the presented scenario is available4 3 Modeling, generating and deploying smart web applications with BESSER BESSER provides the B-UML (BESSER-UML) language, which enables the modeling of smart web applications via three complementary but still interrelated perspectives:structural,agent, andGUIperspectives. | BX3: Moderate | BY3: PDF text extracted from 5 pages; sample evidence page: Not reported. | BZ3: Not reported | CA3: Sample/data adequacy could not be verified from parsed text; No explicit author limitations section found in parsed text | CB3: Not reported | CC3: Not reported | CD3: Not reported | CE3: Not reported | CF3: These actions may include textual responses (e.g., for chat interactions), calls to Python methods (e.g., to invoke external APIs), or operations driven by Large Language Model (LLM) outputs, combining the controlled output from state machines with the openness of LLMs. | CG3: MDE_VISUAL_PROGRAMMING | CH3: AI_AUTOMATION | CI3: MAINTAINABILITY | CJ3: PLATFORM_COMPARISON | CK3: Document Analysis | CL3: Not reported | CM3: =IFERROR(VLOOKUP($A3,Quality_Appraisal!$A:$P,15,FALSE),"") -> 17 | CN3: =IFERROR(VLOOKUP($A3,Quality_Appraisal!$A:$P,16,FALSE),"") -> Moderate | CO3: Yes - central | CP3: Background | CQ3: Languages such as IFML [2], OOWS [3], or UWE [4] are often seen as foundational for the development of traditional UIs. | 2 Demonstration Figure 1 presents the part of BESSER’s pipeline for developing smart web applications used in the demonstration. | The demonstration contains the example of a web application of a library, with a conversational agent responding to frequently asked questions. | CR3: Not reported | CS3: Model-driven / visual programming roots | CT3: Languages such as IFML [2], OOWS [3], or UWE [4] are often seen as foundational for the development of traditional UIs. | 2 Demonstration Figure 1 presents the part of BESSER’s pipeline for developing smart web applications used in the demonstration. | The demonstration contains the example of a web application of a library, with a conversational agent responding to frequently asked questions. | CU3: sample/data size missing; limitations not found | CV3: Not reported | CW3: arXiv:2605.07376v1 [cs.SE] 8 May 2026 (2025). Low-code and no-code with BESSER to create and deploy smart web applications. The peer-reviewed paper will be published in the proceedings of ICWE 2026.; arXiv:2605.07376v1 [cs.SE] 8 May 2026. | CX3: Not reported
A4: P003 | B4: 3.Design Behaviour and Interface Consistency in Generative No-Code Tools A Systematic Literature Review.pdf | C4: research paper\3.Design Behaviour and Interface Consistency in Generative No-Code Tools A Systematic Literature Review.pdf | D4: Completed | E4: 2026-06-12 | F4: Checked - OK | G4: Reported | H4: 4 | I4: Verify automated title/authors/method/sample/theme coding and exact quote page numbers before publication use. | J4: 10.3390/computers15040238 | K4: Design Behaviour and Interface Consistency in Generative No-Code Tools: A Systematic Literature Review | L4: No-Code Tools: A Systematic Literature Review; Gizem Irmak 1,2, * and Qusay H. Mahmoud 1 | M4: 2021 | N4: Review Paper | O4: Licensee MDPI, Basel, Switzerland. | P4: MDPI | Q4: Unclear: discipline not explicitly labeled; paper text concerns LCNC/software systems | R4: generative AI; no-code tools; user interface design; reproducibility; usability; accessibility; ethics 1. | S4: Generative no-code development tools enable users to create applications directly from natural-language prompts, shifting interface design from manual construction to AImediated generation. However, identical prompts frequently produce substantially different user interface (UI) outcomes across tools and even across repeated executions within the same tool. This paper presents a systematic literature review examining how generative no-code systems make design and aesthetic decisions with respect to layout structure, visual consistency, usability, accessibility, and reproducibility. Twenty peer-reviewed studies (2021-2025) were analyzed following a structured review protocol. Existing research predominantly evaluates usability and accessibility in isolation while providing limited insight into aesthetic coherence, design variability, and prompt-to-output stability. Across studies, generative tools exhibit implicit design priors and stochastic behavior that lead to inconsistent visual outcomes and partial misalignment with human-centered design principles. These findings indicate that generative no-code tools do not act as deterministic translators of user intent but instead introduce their own stylistic tendencies. The paper identifies critical evaluation gaps and outlines requirements for future systems, including reproducible generation, transparent design reasoning, and user-directed control, to support reliable and predictable interface development. | T4: Include | U4: 5 | V4: Core focus | W4: Design Behaviour and Interface Consistency in Generative No-Code Tools: A Systematic Literature Review | X4: AI and automation | Y4: Platform comparison; Usability and user experience; Enterprise adoption | Z4: Supports review questions on LCNC adoption, AI automation, methods, benefits, risks, and gaps depending on assigned theme codes. | AA4: These findings indicate that generative no-code tools do not act as deterministic translators of user intent but instead introduce their own stylistic tendencies. | Study Year Methodology and Focus Key Findings and Limitations Zhou T. [15] 2025 Design-to-code pipeline using computer vision and multimodal LLMs to generate UI code from mockups and screenshots. | Study Year Methodology and Focus Key Findings and Limitations Wan Y. [17] 2025 Divide-and-conquer UI generation pipeline using multimo... | AB4: Introduction Low-code/no-code (LCNC) platforms have transformed software development by offering visual environments and pre-built components that require minimal or no programming knowledge. | AC4: Mahmoud 1 1 Department of Electrical, Computer, and Software Engineering, Ontario Tech University, Oshawa, ON L1G 0C5, Canada; qusay.mahmoud@ontariotechu.ca 2 Department of Control and Computer Engineering, Politecnico di Torino, 10129 Torino, Italy * Correspondence: gizem.irmak@studenti.polito.it Abstract Generative no-code development tools enable users to create applications directly from natural-language prompts, shifting interface design from manual construction to AImediated generation. | AD4: low-code; no-code; LCNC; citizen development; visual programming | AE4: Study Year Methodology and Focus Key Findings and Limitations Xu H. [29] 2025 Knowledge-augmented framework using visual prompting and retrieval-augmented generation to convert UI wireframes into React applications. | AF4: generative AI; no-code tools; user interface design; reproducibility; usability; accessibility; ethics 1. | AG4: Generative no-code development tools enable users to create applications directly from natural-language prompts, shifting interface design from manual construction to AImediated generation. However, identical prompts frequently produce substantially different user interface (UI) outcomes across tools and even across repeated executions within the same tool. This paper presents a systematic literature review examining how generative no-code systems make design and aesthetic decisions with respect to layout structure, visual consistency, usability, accessibility, and reproducibility. Twenty peer-reviewed studies (2021-2025) were analyzed following a structured review protocol. Existing research predominantly evaluates usability and accessibility in isolation while providing limited insight into aesthetic coherence, design variability, and prompt-to-output stability. Across studies, generative tools exhibit implicit design priors and stochastic behavior that lead to inconsistent visual outcomes and partial misalignment with human-centered design principles. These findings indicate that generative no-code tools do not act as deterministic translators of user intent but instead introduce their own stylistic tendencies. The paper identifies critical evaluation gaps and outlines requirements for future systems, including reproducible generation, transparent design reasoning, and user-directed control, to support reliable and predictable interface development. | AH4: Literature Review | AI4: Review | AJ4: Systematic Review | AK4: Systematic Review | AL4: Secondary Data | AM4: Published studies/articles | AN4: education | AO4: education | AP4: Mahmoud 1 1 Department of Electrical, Computer, and Software Engineering, Ontario Tech University, Oshawa, ON L1G 0C5, Canada; qusay.mahmoud@ontariotechu.ca 2 Department of Control and Computer Engineering, Politecnico di Torino, 10129 Torino, Italy * Correspondence: gizem.irmak@studenti.polito.it Abstract Generative no-code development tools enable users to create applications directly from natural-language prompts, shifting interface design... | AQ4: AutoGen Studio; ChatGPT | AR4: AutoGen Studio; ChatGPT | AS4: Research Questions This study was guided by one main research question (MRQ) and four supporting sub-questions designed to examine how generative AI-based no-code tools make UI design decisions, how consistent these decisions are, and how well they align with established design principles. • MRQ: How do generative AI-based no-code tools make user interface (UI) design and aesthetic decisions when generating applications from natural-language p... | The protocol defined the research questions, search strategy, eligibility criteria, quality assessment, and data extraction procedures before the search was conducted. | UI Quality Dimension Number of Studies ( n = 20) Layout & Structure 10 Aesthetics & Visual Design 5 Usability & Learnability 5 Accessibility 4 Consistency & Variability 7 Individual studies may contribute to multiple research questions, reflecting the multifaceted nature of generative UI design and evaluation. | AT4: Duan P . [19] 2024 Introduces UICrit dataset with expert UI critiques and applies visually guided few-shot prompting for design feedback generation. | AU4: Frequency of UI quality dimensions assessed across included studies (n = 20). | AV4: In user interface (UI) development, Multimodal Large Language Models (MLLMs) can translate sketches, screenshots, or natural-language descriptions directly into functional code (UI2Code) [5]. | AW4: Mahmoud 1 1 Department of Electrical, Computer, and Software Engineering, Ontario Tech University, Oshawa, ON L1G 0C5, Canada; qusay.mahmoud@ontariotechu.ca 2 Department of Control and Computer Engineering, Politecnico di Torino, 10129 Torino, Italy * Correspondence: gizem.irmak@studenti.polito.it Abstract Generative no-code development tools enable users to create applications directly from natural-language prompts, shifting interface design... | AX4: Database Search Strings Used Total Retrieved Records After Initial Screening IEEE Xplore No-code/low-code AND generative AI/LLM AND UI design 54 44 ACM Digital Library No-code/low-code AND user experience/UI design 60 27 Google Scholar No-code UI design AND evaluation/prompt-based tools 30 18 Searches were restricted to peer-reviewed publication... | AY4: Not reported | AZ4: Systematic Review Design Behaviour and Interface Consistency in Generative No-Code Tools: A Systematic Literature Review Gizem Irmak 1,2, * and Qusay H. | BA4: Adoption is expected to continue growing, with projections indicating use in nearly 70% of enterprise applications by 2025 [3] and approximately 65% of software projects overall [4]. | Computers 2026, 15, 238 2 of 25 models to generate new content and automate development tasks, enhancing LCNC environments by supporting ideation, prototyping, and feature refinement [1]. | Pinho D. [42] 2023 Systematic literature review of 38 studies on usability in low-code platforms. | P . [4] 2024 Systematic literature review of 15 studies on low-code development features, benefits, and challenges. | BB4: Existing research predominantly evaluates usability and accessibility in isolation while providing limited insight into aesthetic coherence, design variability, and prompt-to-output stability. | BC4: Section 7 outlines threats to validity, and Section 8 concludes the paper. | BD4: These findings indicate that generative no-code tools do not act as deterministic translators of user intent but instead introduce their own stylistic tendencies. | Study Year Methodology and Focus Key Findings and Limitations Zhou T. [15] 2025 Design-to-code pipeline using computer vision and multimodal LLMs to generate UI code from mockups and screenshots. | Study Year Methodology and Focus Key Findings and Limitations Wan Y. [17] 2025 Divide-and-conquer UI generation pipeline using multimodal LLMs to decompose screenshots and generate HTML/CSS. | BE4: LCNC solutions are widely adopted because they accelerate development, reduce labor costs, and improve agility, thereby addressing traditional challenges such as delayed delivery and high implementation effort [2]. | While these systems improve development efficiency and accessibility, they also introduce constraints related to scalability, customization, and control, which become particularly relevant in the context of AI-driven interface generation [12]. | BF4: However, identical prompts frequently produce substantially different user interface (UI) outcomes across tools and even across repeated executions within the same tool. | LCNC solutions are widely adopted because they accelerate development, reduce labor costs, and improve agility, thereby addressing traditional challenges such as delayed delivery and high implementation effort [2]. | BG4: Not reported | BH4: Identifies governance risks and mitigation strategies; does not address user-facing UI design or generative interface behavior. | BI4: While these systems improve development efficiency and accessibility, they also introduce constraints related to scalability, customization, and control, which become particularly relevant in the context of AI-driven interface generation [12]. | A. [10], Feng S. [49] Interaction logic Static layout generation Incomplete navigation and cross-page coherence Zhou T. [15] Code usability Structured output in advanced systems Manual effort required for maintainability Zhou T. [15], Wan Y. [17] 5.4. | BJ4: Both approaches abstract implementation details through graphical development environments, enabling faster application creation while reducing reliance on traditional programming. | BK4: Because large language models operate probabilistically, identical prompts may produce different outputs, complicating testing and reproducibility [ 9]. | BL4: Highlights human-AI collaboration in UI design; limited to prototype-level evaluation without analysis of reproducibility or cross-tool variability. | BM4: Highlights workflow trade-offs and educational implications; limited evaluation of detailed UI design and generative variability. | BN4: The integration of LCNC platforms with Generative Artificial Intelligence (GenAI) represents a further shift in software creation workflows. | BO4: This accessibility has contributed to the “democratization” of software creation, enabling non-technical professionals, often referred to as citizen developers, to construct applications quickly and cost-effectively [1]. | BP4: However, identical prompts frequently produce substantially different user interface (UI) outcomes across tools and even across repeated executions within the same tool. | BQ4: These findings indicate that generative no-code tools do not act as deterministic translators of user intent but instead introduce their own stylistic tendencies. | Study Year Methodology and Focus Key Findings and Limitations Zhou T. [15] 2025 Design-to-code pipeline using computer vision and multimodal LLMs to generate UI code from mockups and screenshots. | Study Year Methodology and Focus Key Findings and Limitations Wan Y. [17] 2025 Divide-and-conquer UI generation pipeline using multimodal LLMs to decompose screenshots and generate HTML/CSS. | BR4: The integration of LCNC platforms with Generative Artificial Intelligence (GenAI) represents a further shift in software creation workflows. | BS4: 1 | BT4: Guthardt T. [40] 2024 Empirical comparison of programmers and citizen developers using a prototype no-code builder. | BU4: 7 | BV4: Not reported | BW4: Adoption is expected to continue growing, with projections indicating use in nearly 70% of enterprise applications by 2025 [3] and approximately 65% of software projects overall [4]. | Computers 2026, 15, 238 2 of 25 models to generate new content and automate development tasks, enhancing LCNC environments by supporting ideation, prototyping, and feature refinement [1]. | Pinho D. [42] 2023 Systematic literature review of 38 studies on usability in low-code platforms. | P . [4] 2024 Systematic literature review of 15 studies on low-code development features, benefits, and challenges. | BX4: Strong | BY4: PDF text extracted from 25 pages; sample evidence page: p. 12. | BZ4: inherent to LCNC platforms, such as scalability constraints, hidden platform bugs, and accumulated technical debt, can propagate into generated applications and further reduce reliability [3,22]. 3. Related Work Generative no-code UI research spans three primary directions: platform-oriented studies on low-code/no-code ecosystems, empirical evaluations of AI-generated interfaces, and accessibility or usability assessments. While these works (see Table 2) provide valuable insights into productivity and compliance, they rarely examine design consistency, aesthetic reasoning, or reproducibility across generated interfaces. Consequently, existing literature offers fragmented perspectives on UI quality rather than an integrated understanding of automated design behavior. Table 2. Key related studies on generative no-code and AI-assisted UI design. Study Year Methodology and Focus Key Findings and Limitations Zhou T. [15] 2025 Design-to-code pipeline using computer vision and multimodal LLMs to generate UI code from mockups and screenshots. Structural accuracy; lacks user-centered evaluation. https://doi.org/10.3390/computers15040238 Computers 2026, 15, 238 5 of 25 Table 2. Cont. Study Year Methodology and Focus Key Findings and Limitations Wan Y. [17] 2025 Divide-and-conquer UI generation pipeline using multimodal LLMs to decompose screenshots and generate HTML/CSS. Focus on fide... | CA4: Automated extraction should be checked against the PDF for high-impact fields | CB4: should investigate: • how users form mental models of generative behavior • how interfaces communicate degrees of confidence or stability • how users constrain exploration without over-specifying solutions • how iterative refinement affects trust and perceived control In this context, prompting functions as an ongoing negotiation process. Interfaces that expose alternatives, preserve state across iterations, and communicate change boundaries may improve user confidence and reduce corrective interaction cycles. 6.6. Implications for Software Engineering Research Generative interface development alters the nature of software artifacts from fixed implementations to variable outputs produced by a generation process. As a result, engineering practices must evaluate reliability of the process rather than correctness of a single instance. Quality assurance therefore shifts toward: https://doi.org/10.3390/computers15040238 Computers 2026, 15, 238 21 of 25 • managing prompt and model configu... | CC4: should investigate: • how users form mental models of generative behavior • how interfaces communicate degrees of confidence or stability • how users constrain exploration without over-specifying solutions • how iterative refinement affects trust and perceived control In this context, prompting functions as an ongoing negotiation process. Interfaces that expose alternatives, preserve state across iterations, and communicate change boundaries may improve user confidence and reduce corrective interaction cycles. 6.6. Implications for Software Engineering Research Generative interface development alters the nature of software artifacts from fixed implementations to variable outputs produced by a generation process. As a result, engineering practices must evaluate reliability of the process rather than correctness of a single instance. Quality assurance therefore shifts toward: https://doi.org/10.3390/computers15040238 Computers 2026, 15, 238 21 of 25 • managing prompt and model configu... | CD4: Rather than redefining their general characteristics, this section focuses on their role within contemporary software ecosystems and their implications for automated interface generation. | CE4: Not reported | CF4: Identifies governance risks and mitigation strategies; does not address user-facing UI design or generative interface behavior. | CG4: AI_AUTOMATION | CH4: PLATFORM_COMPARISON | CI4: USABILITY_UX | CJ4: ENTERPRISE_ADOPTION | CK4: Systematic Review | CL4: Not reported | CM4: =IFERROR(VLOOKUP($A4,Quality_Appraisal!$A:$P,15,FALSE),"") -> 24 | CN4: =IFERROR(VLOOKUP($A4,Quality_Appraisal!$A:$P,16,FALSE),"") -> Strong | CO4: Yes - central | CP4: Findings/Future | CQ4: These findings indicate that generative no-code tools do not act as deterministic translators of user intent but instead introduce their own stylistic tendencies. | Study Year Methodology and Focus Key Findings and Limitations Zhou T. [15] 2025 Design-to-code pipeline using computer vision and multimodal LLMs to generate UI code from mockups and screenshots. | Study Year Methodology and Focus Key Findings and Limitations Wan Y. [17] 2025 Divide-and-conquer UI generation pipeline using multimo... | CR4: Not reported | CS4: AI and automation | CT4: These findings indicate that generative no-code tools do not act as deterministic translators of user intent but instead introduce their own stylistic tendencies. | Study Year Methodology and Focus Key Findings and Limitations Zhou T. [15] 2025 Design-to-code pipeline using computer vision and multimodal LLMs to generate UI code from mockups and screenshots. | Study Year Methodology and Focus Key Findings and Limitations Wan Y. [17] 2025 Divide-and-conquer UI generation pipeline using multimo... | CU4: None beyond normal human verification of automated extraction | CV4: Not reported | CW4: No-Code Tools: A Systematic Literature Review; Gizem Irmak 1,2, * and Qusay H. Mahmoud 1 (2021). Design Behaviour and Interface Consistency in Generative No-Code Tools: A Systematic Literature Review. Licensee MDPI, Basel, Switzerland.. | CX4: https://doi.org/10.3390/computers15040238
